<?xml version="1.0" ?>
<sdf version="1.5">
  <model name="pioneer3at">
    <pose>0 0 0.180 0 0 0</pose>
    <static>false</static>
    <link name="chassis">
      <inertial>
        <mass>14.0</mass>
        <inertia>
          <ixx>0.147116667</ixx>
          <iyy>0.334951167</iyy>
          <izz>0.3978345</izz>
	  <ixy>0.0</ixy>
          <ixz>0.0</ixz>
          <iyz>0.0</iyz>
        </inertia>
      </inertial>
      <collision name="collision">
        <geometry>
          <box>
            <size>0.501 0.300 0.19</size>
          </box>
        </geometry>
      </collision>
      <visual name="visual">
        <geometry>
          <mesh>
            <uri>model://pioneer3at/meshes/chassis.dae</uri>
          </mesh>
        </geometry>
      </visual>
    </link>
    <link name="right_front_wheel">
      <pose>0.125 -0.201 -0.06 1.5707 0 0</pose>

      <inertial>
        <mass>1.5</mass>
        <inertia>
          <ixx>0.005240625</ixx>
          <iyy>0.005240625</iyy>
          <izz>0.009075</izz>
          <ixy>0</ixy>
          <ixz>0</ixz>
          <iyz>0</iyz>
        </inertia>
      </inertial>

      <collision name="collision">
        <geometry>
          <cylinder>
            <radius>0.110</radius>
            <length>0.075</length>
          </cylinder>
        </geometry>
        <surface>
          <friction>
            <ode>
              <mu>100000.0</mu>
              <mu2>100000.0</mu2>
              <slip1>0</slip1>
              <slip2>0</slip2>
            </ode>
          </friction>
        </surface>
      </collision>
      <visual name="visual">
        <geometry>
          <mesh>
            <uri>model://pioneer3at/meshes/wheel.dae</uri>
          </mesh>
        </geometry>
      </visual>
    </link>
    <link name="left_front_wheel">
      <pose>0.125 0.201 -0.06 1.5707 0 0</pose>

      <inertial>
        <mass>1.5</mass>
        <inertia>
          <ixx>0.005240625</ixx>
          <iyy>0.005240625</iyy>
          <izz>0.009075</izz>
          <ixy>0</ixy>
          <ixz>0</ixz>
          <iyz>0</iyz>
        </inertia>
      </inertial>

      <collision name="collision">
        <geometry>
          <cylinder>
            <radius>0.110</radius>
            <length>0.075</length>
          </cylinder>
        </geometry>
        <surface>
          <friction>
            <ode>
              <mu>100000.0</mu>
              <mu2>100000.0</mu2>
              <slip1>0</slip1>
              <slip2>0</slip2>
            </ode>
          </friction>
        </surface>
      </collision>
      <visual name="visual">
        <geometry>
          <mesh>
            <uri>model://pioneer3at/meshes/wheel.dae</uri>
          </mesh>
        </geometry>
      </visual>
    </link>
    <link name="right_rear_wheel">
      <pose>-0.125 -0.201 -0.06 1.5707 0 0</pose>

      <inertial>
        <mass>1.5</mass>
        <inertia>
          <ixx>0.005240625</ixx>
          <iyy>0.005240625</iyy>
          <izz>0.009075</izz>
          <ixy>0</ixy>
          <ixz>0</ixz>
          <iyz>0</iyz>
        </inertia>
      </inertial>

      <collision name="collision">
        <geometry>
          <cylinder>
            <radius>0.110</radius>
            <length>0.075</length>
          </cylinder>
        </geometry>
        <surface>
          <friction>
            <ode>
              <mu>100000.0</mu>
              <mu2>100000.0</mu2>
              <slip1>0</slip1>
              <slip2>0</slip2>
            </ode>
          </friction>
        </surface>
      </collision>
      <visual name="visual">
        <geometry>
          <mesh>
            <uri>model://pioneer3at/meshes/wheel.dae</uri>
          </mesh>
        </geometry>
      </visual>
    </link>
    <link name="left_rear_wheel">
      <pose>-0.125 0.201 -0.06 1.5707 0 0</pose>

      <inertial>
        <mass>1.5</mass>
        <inertia>
          <ixx>0.005240625</ixx>
          <iyy>0.005240625</iyy>
          <izz>0.009075</izz>
          <ixy>0</ixy>
          <ixz>0</ixz>
          <iyz>0</iyz>
        </inertia>
      </inertial>

      <collision name="collision">
        <geometry>
          <cylinder>
            <radius>0.110</radius>
            <length>0.075</length>
          </cylinder>
        </geometry>
        <surface>
          <friction>
            <ode>
              <mu>100000.0</mu>
              <mu2>100000.0</mu2>
              <slip1>0</slip1>
              <slip2>0</slip2>
            </ode>
          </friction>
        </surface>
      </collision>
      <visual name="visual">
        <geometry>
          <mesh>
            <uri>model://pioneer3at/meshes/wheel.dae</uri>
          </mesh>
        </geometry>
      </visual>
    </link>
    <joint type="revolute" name="right_front">
      <pose>0 0 0 0 0 0</pose>
      <child>right_front_wheel</child>
      <parent>chassis</parent>
      <axis>
        <xyz>0 1 0</xyz>
        <use_parent_model_frame>true</use_parent_model_frame>
      </axis>
    </joint>
    <joint type="revolute" name="right_rear">
      <pose>0 0 0 0 0 0</pose>
      <child>right_rear_wheel</child>
      <parent>chassis</parent>
      <axis>
        <xyz>0 1 0</xyz>
        <use_parent_model_frame>true</use_parent_model_frame>
      </axis>
    </joint>
    <joint type="revolute" name="left_front">
      <pose>0 0 0 0 0 0</pose>
      <child>left_front_wheel</child>
      <parent>chassis</parent>
      <axis>
        <xyz>0 1 0</xyz>
        <use_parent_model_frame>true</use_parent_model_frame>
      </axis>
    </joint>
    <joint type="revolute" name="left_rear">
      <pose>0 0 0 0 0 0</pose>
      <child>left_rear_wheel</child>
      <parent>chassis</parent>
      <axis>
        <xyz>0 1 0</xyz>
        <use_parent_model_frame>true</use_parent_model_frame>
      </axis>
    </joint>
    
    <plugin name="skid_steer_drive" filename="libgazebo_ros_diff_drive.so">

       <ros>
          <namespace>/p3at</namespace>
        <!--  <remapping>cmd_vel:=cmd_demo</remapping>
          <remapping>odom:=odom_demo</remapping> -->
        </ros>

	<updateRate>100.0</updateRate>
	
      <num_wheel_pairs>2</num_wheel_pairs>
      
      <right_joint>right_front</right_joint>
      <left_joint>left_front</left_joint>

      <right_joint>right_rear</right_joint>
      <left_joint>left_rear</left_joint>

       <wheel_separation>0.4</wheel_separation>       
        <wheel_separation>0.4</wheel_separation>
        <wheel_diameter>0.215</wheel_diameter>
	<wheel_diameter>0.215</wheel_diameter>

      	<!-- limits -->
        <max_wheel_torque>35</max_wheel_torque>
        <max_wheel_acceleration>0.5</max_wheel_acceleration>

        <!-- output -->
        <publish_odom>true</publish_odom>
        <publish_odom_tf>true</publish_odom_tf>
        <publish_wheel_tf>true</publish_wheel_tf>

    </plugin>

    <!-- Add the laser range finder -->
       <link name="laser_link">
         <inertial>
           <!-- Mass of the laser range finder in kg -->
           <mass>0.1</mass>
         </inertial>
         <!-- Position is towards the front of the robot -->
         <!-- Laser finder is mounted on top -->
         <pose>0.2 0 0.13 0 0 0</pose>
         
         <!-- Add a mesh to make it more visually appealing -->
         <visual name="visual">
           <geometry>
             <mesh>
	       
               <uri>model://hokuyo/meshes/hokuyo.dae</uri>
	       <!--
	       <uri>model://husky/meshes/lms1xx_mount.dae</uri>
-->
             </mesh>
           </geometry>
         </visual>
         
         <!-- Collision properties of the base of the laser range finder-->
         <collision name="collision-base">
           <pose>0 0 -0.0145 0 0 0</pose>
           <geometry>
             <box>
               <size>0.05 0.05 0.041</size>
             </box>
           </geometry>
         </collision>
         <!-- Collision properties of the top of the laser range finder-->
         <collision name="collision-top">
           <pose>0 0 0.0205 0 0 0</pose>
           <geometry>
             <cylinder>
               <radius>0.021</radius>
               <length>0.029</length>
             </cylinder>
           </geometry>
         </collision>
         
         <!-- Describes the type and properties of the sensor -->
	 <sensor name="laser" type="ray">
	   <pose>0.01 0 0.0175 0 -0 0</pose>
           <ray>
             <scan>
               <horizontal>
                 <samples>181</samples>
                 <resolution>1</resolution>
                 <min_angle>-1.57080</min_angle>
                 <max_angle>1.57080</max_angle>
               </horizontal>
             </scan>
             <range>
               <min>0.08</min>
               <max>10</max>
               <resolution>0.05</resolution>
             </range>
           </ray>
           <always_on>1</always_on>
           <update_rate>10</update_rate>
           <visualize>false</visualize>  <!-- set this to true if you want to visualize the rays -->

           <plugin name='laser' filename='libgazebo_ros_ray_sensor.so'>
             <ros>
               <namespace>/p3at</namespace>
	       <remapping>~/out:=scan</remapping>
             </ros>
             <output_type>sensor_msgs/LaserScan</output_type>
           </plugin>
	 </sensor>
       </link>
     
 <!-- Connect laser range finder to the robot's body -->
       <joint type="fixed" name="laser_joint">
         <child>laser_link</child>
         <parent>chassis</parent>
       </joint>

       
  </model>
</sdf>
